<?xml version="1.0" encoding="utf-8" standalone="no"?>
<!--This file represents the results of running a test suite-->
<test-results name="D:\Todo de la U\Ingenieria de calidad\testUnitCalidad\Practica2Sample\UnitTest\UnitTest\bin\Debug\UnitTest.dll" total="6" errors="0" failures="2" not-run="0" inconclusive="0" ignored="0" skipped="0" invalid="0" date="2015-11-01" time="18:15:20">
  <environment nunit-version="2.6.4.14350" clr-version="2.0.50727.7905" os-version="Microsoft Windows NT 6.2.9200.0" platform="Win32NT" cwd="C:\Program Files (x86)\NUnit 2.6.4\bin" machine-name="EQUIPO-SERGIO" user="Sergio" user-domain="EQUIPO-SERGIO" />
  <culture-info current-culture="es-US" current-uiculture="es-ES" />
  <test-suite type="Assembly" name="D:\Todo de la U\Ingenieria de calidad\testUnitCalidad\Practica2Sample\UnitTest\UnitTest\bin\Debug\UnitTest.dll" executed="True" result="Failure" success="False" time="0.073" asserts="0">
    <results>
      <test-suite type="Namespace" name="UnitTest" executed="True" result="Failure" success="False" time="0.072" asserts="0">
        <results>
          <test-suite type="TestFixture" name="DiscountTest" executed="True" result="Failure" success="False" time="0.072" asserts="0">
            <results>
              <test-case name="UnitTest.DiscountTest.TestDiscountPricefiftyPercent" executed="True" result="Success" success="True" time="0.000" asserts="1" />
              <test-case name="UnitTest.DiscountTest.TestDiscountPriceFivePercent" executed="True" result="Success" success="True" time="0.000" asserts="1" />
              <test-case name="UnitTest.DiscountTest.TestDiscountPriceTenPercent" executed="True" result="Success" success="True" time="0.000" asserts="1" />
              <test-case name="UnitTest.DiscountTest.TestExceptionwithCero" executed="True" result="Failure" success="False" time="0.000" asserts="0">
                <failure>
                  <message><![CDATA[An unexpected exception type was thrown
Expected: System.ArgumentOutOfRangeException
 but was: System.ArgumentException :  Sales Amount should not be 'Zero/Negative']]></message>
                  <stack-trace><![CDATA[en UnitTest.Discount.calculateDiscount(Double SalesAmnt) en d:\Todo de la U\Ingenieria de calidad\testUnitCalidad\Practica2Sample\UnitTest\UnitTest\Discount.cs:línea 18
en UnitTest.DiscountTest.TestExceptionwithCero() en d:\Todo de la U\Ingenieria de calidad\testUnitCalidad\Practica2Sample\UnitTest\UnitTest\DiscountTest.cs:línea 28
]]></stack-trace>
                </failure>
              </test-case>
              <test-case name="UnitTest.DiscountTest.TestExceptionwithCero1" executed="True" result="Failure" success="False" time="0.001" asserts="1">
                <failure>
                  <message><![CDATA[  Expected: <System.Exception>
  But was:  <System.ArgumentException> ( Sales Amount should not be 'Zero/Negative')
   en UnitTest.Discount.calculateDiscount(Double SalesAmnt) en d:\Todo de la U\Ingenieria de calidad\testUnitCalidad\Practica2Sample\UnitTest\UnitTest\Discount.cs:línea 18
   en UnitTest.DiscountTest.<>c__DisplayClass1.<TestExceptionwithCero1>b__0() en d:\Todo de la U\Ingenieria de calidad\testUnitCalidad\Practica2Sample\UnitTest\UnitTest\DiscountTest.cs:línea 17
   en NUnit.Framework.Assert.Throws(IResolveConstraint expression, TestDelegate code, String message, Object[] args)
]]></message>
                  <stack-trace><![CDATA[en UnitTest.DiscountTest.TestExceptionwithCero1() en d:\Todo de la U\Ingenieria de calidad\testUnitCalidad\Practica2Sample\UnitTest\UnitTest\DiscountTest.cs:línea 17
]]></stack-trace>
                </failure>
              </test-case>
              <test-case name="UnitTest.DiscountTest.TestNoDiscount" executed="True" result="Success" success="True" time="0.000" asserts="1" />
            </results>
          </test-suite>
        </results>
      </test-suite>
    </results>
  </test-suite>
</test-results>